Workbook
Name NativeTimeline_ORDER_DATE: #N/A
Name Slicer_DEAL_SIZE: #N/A
Name Slicer_PRODUCT_LINE: #N/A
Name Slicer_TERRITORY: #N/A

Sheet Sales
A1: QUANTITY ORDERED | B1: PRICE EACH | C1: SALES | D1: ORDER DATE | E1: STATUS | F1: QTR_ID | G1: MONTH_ID | H1: YEAR_ID | I1: PRODUCT LINE | J1: MSRP | K1: PRICE VARIANCE | L1: AVG DISCOUNT | M1: DISCOUNT RANGE | N1: CITY | O1: COUNTRY | P1: TERRITORY | Q1: DEAL SIZE
A2: 30 | B2: 95.7 | C2: =Sales!$B2*Sales!$A2 -> 2871 | D2: 37676 | E2: Shipped | F2: 1 | G2: 2 | H2: 2003 | I2: Motorcycles | J2: 95 | K2: =Sales!$B2-Sales!$J2 -> 0.7 | L2: =(Sales!$J2-Sales!$B2)/Sales!$J2 -> -0.0073684211 | M2: =IF(L2<0%,"Below 0%",IF(L2=0%,"0%",IF(AND(L2<=5%,L2>0%),"0%-5%",IF(AND(L2<=10%,L2>5%),"5%-10%",IF(AND(L2<=15%,L2>10%),"10%-15%",IF(AND(L2<=20%,L2>15%),"15%-20%","+20%")))))) -> Below 0% | N2: NYC | O2: USA | P2: NA | Q2: Small
A3: 34 | B3: 81.35 | C3: =Sales!$B3*Sales!$A3 -> 2765.9 | D3: 37748 | E3: Shipped | F3: 2 | G3: 5 | H3: 2003 | I3: Motorcycles | J3: 95 | K3: =Sales!$B3-Sales!$J3 -> -13.65 | L3: =(Sales!$J3-Sales!$B3)/Sales!$J3 -> 0.14368421 | M3: =IF(L3<0%,"Below 0%",IF(L3=0%,"0%",IF(AND(L3<=5%,L3>0%),"0%-5%",IF(AND(L3<=10%,L3>5%),"5%-10%",IF(AND(L3<=15%,L3>10%),"10%-15%",IF(AND(L3<=20%,L3>15%),"15%-20%","+20%")))))) -> 10%-15% | N3: Reims | O3: France | P3: EMEA | Q3: Small
A4: 41 | B4: 94.74 | C4: =Sales!$B4*Sales!$A4 -> 3884.34 | D4: 37803 | E4: Shipped | F4: 3 | G4: 7 | H4: 2003 | I4: Motorcycles | J4: 95 | K4: =Sales!$B4-Sales!$J4 -> -0.26 | L4: =(Sales!$J4-Sales!$B4)/Sales!$J4 -> 0.0027368421 | M4: 0% | N4: Paris | O4: France | P4: EMEA | Q4: Medium
A5: 45 | B5: 83.26 | C5: =Sales!$B5*Sales!$A5 -> 3746.7 | D5: 37858 | E5: Shipped | F5: 3 | G5: 8 | H5: 2003 | I5: Motorcycles | J5: 95 | K5: =Sales!$B5-Sales!$J5 -> -11.74 | L5: =(Sales!$J5-Sales!$B5)/Sales!$J5 -> 0.12357895 | M5: =IF(L5<0%,"Below 0%",IF(L5=0%,"0%",IF(AND(L5<=5%,L5>0%),"0%-5%",IF(AND(L5<=10%,L5>5%),"5%-10%",IF(AND(L5<=15%,L5>10%),"10%-15%",IF(AND(L5<=20%,L5>15%),"15%-20%","+20%")))))) -> 10%-15% | N5: Pasadena | O5: USA | P5: NA | Q5: Medium
A6: 49 | B6: 100 | C6: =Sales!$B6*Sales!$A6 -> 4900 | D6: 37904 | E6: Shipped | F6: 4 | G6: 10 | H6: 2003 | I6: Motorcycles | J6: 95 | K6: =Sales!$B6-Sales!$J6 -> 5 | L6: =(Sales!$J6-Sales!$B6)/Sales!$J6 -> -0.052631579 | M6: =IF(L6<0%,"Below 0%",IF(L6=0%,"0%",IF(AND(L6<=5%,L6>0%),"0%-5%",IF(AND(L6<=10%,L6>5%),"5%-10%",IF(AND(L6<=15%,L6>10%),"10%-15%",IF(AND(L6<=20%,L6>15%),"15%-20%","+20%")))))) -> Below 0% | N6: San Francisco | O6: USA | P6: NA | Q6: Medium
A7: 36 | B7: 96.66 | C7: =Sales!$B7*Sales!$A7 -> 3479.76 | D7: 37922 | E7: Shipped | F7: 4 | G7: 10 | H7: 2003 | I7: Motorcycles | J7: 95 | K7: =Sales!$B7-Sales!$J7 -> 1.66 | L7: =(Sales!$J7-Sales!$B7)/Sales!$J7 -> -0.017473684 | M7: =IF(L7<0%,"Below 0%",IF(L7=0%,"0%",IF(AND(L7<=5%,L7>0%),"0%-5%",IF(AND(L7<=10%,L7>5%),"5%-10%",IF(AND(L7<=15%,L7>10%),"10%-15%",IF(AND(L7<=20%,L7>15%),"15%-20%","+20%")))))) -> Below 0% | N7: Burlingame | O7: USA | P7: NA | Q7: Medium
A8: 29 | B8: 86.13 | C8: =Sales!$B8*Sales!$A8 -> 2497.77 | D8: 37936 | E8: Shipped | F8: 4 | G8: 11 | H8: 2003 | I8: Motorcycles | J8: 95 | K8: =Sales!$B8-Sales!$J8 -> -8.87 | L8: =(Sales!$J8-Sales!$B8)/Sales!$J8 -> 0.093368421 | M8: =IF(L8<0%,"Below 0%",IF(L8=0%,"0%",IF(AND(L8<=5%,L8>0%),"0%-5%",IF(AND(L8<=10%,L8>5%),"5%-10%",IF(AND(L8<=15%,L8>10%),"10%-15%",IF(AND(L8<=20%,L8>15%),"15%-20%","+20%")))))) -> 5%-10% | N8: Lille | O8: France | P8: EMEA | Q8: Small
A9: 48 | B9: 100 | C9: =Sales!$B9*Sales!$A9 -> 4800 | D9: 37943 | E9: Shipped | F9: 4 | G9: 11 | H9: 2003 | I9: Motorcycles | J9: 95 | K9: =Sales!$B9-Sales!$J9 -> 5 | L9: =(Sales!$J9-Sales!$B9)/Sales!$J9 -> -0.052631579 | M9: =IF(L9<0%,"Below 0%",IF(L9=0%,"0%",IF(AND(L9<=5%,L9>0%),"0%-5%",IF(AND(L9<=10%,L9>5%),"5%-10%",IF(AND(L9<=15%,L9>10%),"10%-15%",IF(AND(L9<=20%,L9>15%),"15%-20%","+20%")))))) -> Below 0% | N9: Bergen | O9: Norway | P9: EMEA | Q9: Medium
A10: 22 | B10: 98.57 | C10: =Sales!$B10*Sales!$A10 -> 2168.54 | D10: 37956 | E10: Shipped | F10: 4 | G10: 12 | H10: 2003 | I10: Motorcycles | J10: 95 | K10: =Sales!$B10-Sales!$J10 -> 3.57 | L10: =(Sales!$J10-Sales!$B10)/Sales!$J10 -> -0.037578947 | M10: =IF(L10<0%,"Below 0%",IF(L10=0%,"0%",IF(AND(L10<=5%,L10>0%),"0%-5%",IF(AND(L10<=10%,L10>5%),"5%-10%",IF(AND(L10<=15%,L10>10%),"10%-15%",IF(AND(L10<=20%,L10>15%),"15%-20%","+20%")))))) -> Below 0% | N10: San Francisco | O10: USA | P10: NA | Q10: Small
A11: 41 | B11: 100 | C11: =Sales!$B11*Sales!$A11 -> 4100 | D11: 38001 | E11: Shipped | F11: 1 | G11: 1 | H11: 2004 | I11: Motorcycles | J11: 95 | K11: =Sales!$B11-Sales!$J11 -> 5 | L11: =(Sales!$J11-Sales!$B11)/Sales!$J11 -> -0.052631579 | M11: =IF(L11<0%,"Below 0%",IF(L11=0%,"0%",IF(AND(L11<=5%,L11>0%),"0%-5%",IF(AND(L11<=10%,L11>5%),"5%-10%",IF(AND(L11<=15%,L11>10%),"10%-15%",IF(AND(L11<=20%,L11>15%),"15%-20%","+20%")))))) -> Below 0% | N11: Paris | O11: France | P11: EMEA | Q11: Medium
A12: 37 | B12: 100 | C12: =Sales!$B12*Sales!$A12 -> 3700 | D12: 38037 | E12: Shipped | F12: 1 | G12: 2 | H12: 2004 | I12: Motorcycles | J12: 95 | K12: =Sales!$B12-Sales!$J12 -> 5 | L12: =(Sales!$J12-Sales!$B12)/Sales!$J12 -> -0.052631579 | M12: =IF(L12<0%,"Below 0%",IF(L12=0%,"0%",IF(AND(L12<=5%,L12>0%),"0%-5%",IF(AND(L12<=10%,L12>5%),"5%-10%",IF(AND(L12<=15%,L12>10%),"10%-15%",IF(AND(L12<=20%,L12>15%),"15%-20%","+20%")))))) -> Below 0% | N12: Melbourne | O12: Australia | P12: APAC | Q12: Medium
A13: 23 | B13: 100 | C13: =Sales!$B13*Sales!$A13 -> 2300 | D13: 38082 | E13: Shipped | F13: 2 | G13: 4 | H13: 2004 | I13: Motorcycles | J13: 95 | K13: =Sales!$B13-Sales!$J13 -> 5 | L13: =(Sales!$J13-Sales!$B13)/Sales!$J13 -> -0.052631579 | M13: =IF(L13<0%,"Below 0%",IF(L13=0%,"0%",IF(AND(L13<=5%,L13>0%),"0%-5%",IF(AND(L13<=10%,L13>5%),"5%-10%",IF(AND(L13<=15%,L13>10%),"10%-15%",IF(AND(L13<=20%,L13>15%),"15%-20%","+20%")))))) -> Below 0% | N13: NYC | O13: USA | P13: NA | Q13: Small
A14: 28 | B14: 100 | C14: =Sales!$B14*Sales!$A14 -> 2800 | D14: 38125 | E14: Shipped | F14: 2 | G14: 5 | H14: 2004 | I14: Motorcycles | J14: 95 | K14: =Sales!$B14-Sales!$J14 -> 5 | L14: =(Sales!$J14-Sales!$B14)/Sales!$J14 -> -0.052631579 | M14: =IF(L14<0%,"Below 0%",IF(L14=0%,"0%",IF(AND(L14<=5%,L14>0%),"0%-5%",IF(AND(L14<=10%,L14>5%),"5%-10%",IF(AND(L14<=15%,L14>10%),"10%-15%",IF(AND(L14<=20%,L14>15%),"15%-20%","+20%")))))) -> Below 0% | N14: Newark | O14: USA | P14: NA | Q14: Medium
A15: 34 | B15: 100 | C15: =Sales!$B15*Sales!$A15 -> 3400 | D15: 38166 | E15: Shipped | F15: 2 | G15: 6 | H15: 2004 | I15: Motorcycles | J15: 95 | K15: =Sales!$B15-Sales!$J15 -> 5 | L15: =(Sales!$J15-Sales!$B15)/Sales!$J15 -> -0.052631579 | M15: =IF(L15<0%,"Below 0%",IF(L15=0%,"0%",IF(AND(L15<=5%,L15>0%),"0%-5%",IF(AND(L15<=10%,L15>5%),"5%-10%",IF(AND(L15<=15%,L15>10%),"10%-15%",IF(AND(L15<=20%,L15>15%),"15%-20%","+20%")))))) -> Below 0% | N15: Bridgewater | O15: USA | P15: NA | Q15: Medium
A16: 45 | B16: 92.83 | C16: =Sales!$B16*Sales!$A16 -> 4177.35 | D16: 38191 | E16: Shipped | F16: 3 | G16: 7 | H16: 2004 | I16: Motorcycles | J16: 95 | K16: =Sales!$B16-Sales!$J16 -> -2.17 | L16: =(Sales!$J16-Sales!$B16)/Sales!$J16 -> 0.022842105 | M16: =IF(L16<0%,"Below 0%",IF(L16=0%,"0%",IF(AND(L16<=5%,L16>0%),"0%-5%",IF(AND(L16<=10%,L16>5%),"5%-10%",IF(AND(L16<=15%,L16>10%),"10%-15%",IF(AND(L16<=20%,L16>15%),"15%-20%","+20%")))))) -> 0%-5% | N16: Nantes | O16: France | P16: EMEA | Q16: Medium
... A19: 41 | B19: 100 | C19: =Sales!$B19*Sales!$A19 -> 4100 | D19: 38275 | E19: Shipped | F19: 4 | G19: 10 | H19: 2004 | I19: Motorcycles | J19: 95 | K19: =Sales!$B19-Sales!$J19 -> 5 | L19: =(Sales!$J19-Sales!$B19)/Sales!$J19 -> -0.052631579 | M19: =IF(L19<0%,"Below 0%",IF(L19=0%,"0%",IF(AND(L19<=5%,L19>0%),"0%-5%",IF(AND(L19<=10%,L19>5%),"5%-10%",IF(AND(L19<=15%,L19>10%),"10%-15%",IF(AND(L19<=20%,L19>15%),"15%-20%","+20%")))))) -> Below 0% | N19: Stavern | O19: Norway | P19: EMEA | Q19: Medium
A20: 46 | B20: 94.74 | C20: =Sales!$B20*Sales!$A20 -> 4358.04 | D20: 38293 | E20: Shipped | F20: 4 | G20: 11 | H20: 2004 | I20: Motorcycles | J20: 95 | K20: =Sales!$B20-Sales!$J20 -> -0.26 | L20: =(Sales!$J20-Sales!$B20)/Sales!$J20 -> 0.0027368421 | M20: 0% | N20: Allentown | O20: USA | P20: NA | Q20: Medium
A21: 42 | B21: 100 | C21: =Sales!$B21*Sales!$A21 -> 4200 | D21: 38306 | E21: Shipped | F21: 4 | G21: 11 | H21: 2004 | I21: Motorcycles | J21: 95 | K21: =Sales!$B21-Sales!$J21 -> 5 | L21: =(Sales!$J21-Sales!$B21)/Sales!$J21 -> -0.052631579 | M21: =IF(L21<0%,"Below 0%",IF(L21=0%,"0%",IF(AND(L21<=5%,L21>0%),"0%-5%",IF(AND(L21<=10%,L21>5%),"5%-10%",IF(AND(L21<=15%,L21>10%),"10%-15%",IF(AND(L21<=20%,L21>15%),"15%-20%","+20%")))))) -> Below 0% | N21: NYC | O21: USA | P21: NA | Q21: Medium
A22: 41 | B22: 100 | C22: =Sales!$B22*Sales!$A22 -> 4100 | D22: 38315 | E22: Shipped | F22: 4 | G22: 11 | H22: 2004 | I22: Motorcycles | J22: 95 | K22: =Sales!$B22-Sales!$J22 -> 5 | L22: =(Sales!$J22-Sales!$B22)/Sales!$J22 -> -0.052631579 | M22: =IF(L22<0%,"Below 0%",IF(L22=0%,"0%",IF(AND(L22<=5%,L22>0%),"0%-5%",IF(AND(L22<=10%,L22>5%),"5%-10%",IF(AND(L22<=15%,L22>10%),"10%-15%",IF(AND(L22<=20%,L22>15%),"15%-20%","+20%")))))) -> Below 0% | N22: Salzburg | O22: Austria | P22: EMEA | Q22: Large
A23: 20 | B23: 72.55 | C23: =Sales!$B23*Sales!$A23 -> 1451 | D23: 38338 | E23: Shipped | F23: 4 | G23: 12 | H23: 2004 | I23: Motorcycles | J23: 95 | K23: =Sales!$B23-Sales!$J23 -> -22.45 | L23: =(Sales!$J23-Sales!$B23)/Sales!$J23 -> 0.23631579 | M23: =IF(L23<0%,"Below 0%",IF(L23=0%,"0%",IF(AND(L23<=5%,L23>0%),"0%-5%",IF(AND(L23<=10%,L23>5%),"5%-10%",IF(AND(L23<=15%,L23>10%),"10%-15%",IF(AND(L23<=20%,L23>15%),"15%-20%","+20%")))))) -> +20% | N23: Chatswood | O23: Australia | P23: APAC | Q23: Small
A24: 21 | B24: 34.91 | C24: =Sales!$B24*Sales!$A24 -> 733.11 | D24: 38386 | E24: Shipped | F24: 1 | G24: 2 | H24: 2005 | I24: Motorcycles | J24: 95 | K24: =Sales!$B24-Sales!$J24 -> -60.09 | L24: =(Sales!$J24-Sales!$B24)/Sales!$J24 -> 0.63252632 | M24: =IF(L24<0%,"Below 0%",IF(L24=0%,"0%",IF(AND(L24<=5%,L24>0%),"0%-5%",IF(AND(L24<=10%,L24>5%),"5%-10%",IF(AND(L24<=15%,L24>10%),"10%-15%",IF(AND(L24<=20%,L24>15%),"15%-20%","+20%")))))) -> +20% | N24: Nantes | O24: France | P24: EMEA | Q24: Small
A25: 42 | B25: 76.36 | C25: =Sales!$B25*Sales!$A25 -> 3207.12 | D25: 38414 | E25: Shipped | F25: 1 | G25: 3 | H25: 2005 | I25: Motorcycles | J25: 95 | K25: =Sales!$B25-Sales!$J25 -> -18.64 | L25: =(Sales!$J25-Sales!$B25)/Sales!$J25 -> 0.19621053 | M25: =IF(L25<0%,"Below 0%",IF(L25=0%,"0%",IF(AND(L25<=5%,L25>0%),"0%-5%",IF(AND(L25<=10%,L25>5%),"5%-10%",IF(AND(L25<=15%,L25>10%),"10%-15%",IF(AND(L25<=20%,L25>15%),"15%-20%","+20%")))))) -> 15%-20% | N25: New Bedford | O25: USA | P25: NA | Q25: Medium
A26: 24 | B26: 100 | C26: =Sales!$B26*Sales!$A26 -> 2400 | D26: 38450 | E26: Shipped | F26: 2 | G26: 4 | H26: 2005 | I26: Motorcycles | J26: 95 | K26: =Sales!$B26-Sales!$J26 -> 5 | L26: =(Sales!$J26-Sales!$B26)/Sales!$J26 -> -0.052631579 | M26: =IF(L26<0%,"Below 0%",IF(L26=0%,"0%",IF(AND(L26<=5%,L26>0%),"0%-5%",IF(AND(L26<=10%,L26>5%),"5%-10%",IF(AND(L26<=15%,L26>10%),"10%-15%",IF(AND(L26<=20%,L26>15%),"15%-20%","+20%")))))) -> Below 0% | N26: Liverpool | O26: UK | P26: EMEA | Q26: Small
A27: 66 | B27: 100 | C27: =Sales!$B27*Sales!$A27 -> 6600 | D27: 38485 | E27: Disputed | F27: 2 | G27: 5 | H27: 2005 | I27: Motorcycles | J27: 95 | K27: =Sales!$B27-Sales!$J27 -> 5 | L27: =(Sales!$J27-Sales!$B27)/Sales!$J27 -> -0.052631579 | M27: =IF(L27<0%,"Below 0%",IF(L27=0%,"0%",IF(AND(L27<=5%,L27>0%),"0%-5%",IF(AND(L27<=10%,L27>5%),"5%-10%",IF(AND(L27<=15%,L27>10%),"10%-15%",IF(AND(L27<=20%,L27>15%),"15%-20%","+20%")))))) -> Below 0% | N27: Madrid | O27: Spain | P27: EMEA | Q27: Large
A28: 26 | B28: 100 | C28: =Sales!$B28*Sales!$A28 -> 2600 | D28: 37650 | E28: Shipped | F28: 1 | G28: 1 | H28: 2003 | I28: Classic Cars | J28: 214 | K28: =Sales!$B28-Sales!$J28 -> -114 | L28: =(Sales!$J28-Sales!$B28)/Sales!$J28 -> 0.53271028 | M28: =IF(L28<0%,"Below 0%",IF(L28=0%,"0%",IF(AND(L28<=5%,L28>0%),"0%-5%",IF(AND(L28<=10%,L28>5%),"5%-10%",IF(AND(L28<=15%,L28>10%),"10%-15%",IF(AND(L28<=20%,L28>15%),"15%-20%","+20%")))))) -> +20% | N28: Stavern | O28: Norway | P28: EMEA | Q28: Medium
A29: 29 | B29: 100 | C29: =Sales!$B29*Sales!$A29 -> 2900 | D29: 37704 | E29: Shipped | F29: 1 | G29: 3 | H29: 2003 | I29: Classic Cars | J29: 214 | K29: =Sales!$B29-Sales!$J29 -> -114 | L29: =(Sales!$J29-Sales!$B29)/Sales!$J29 -> 0.53271028 | M29: =IF(L29<0%,"Below 0%",IF(L29=0%,"0%",IF(AND(L29<=5%,L29>0%),"0%-5%",IF(AND(L29<=10%,L29>5%),"5%-10%",IF(AND(L29<=15%,L29>10%),"10%-15%",IF(AND(L29<=20%,L29>15%),"15%-20%","+20%")))))) -> +20% | N29: Lule | O29: Sweden | P29: EMEA | Q29: Large
A30: 38 | B30: 100 | C30: =Sales!$B30*Sales!$A30 -> 3800 | D30: 37769 | E30: Shipped | F30: 2 | G30: 5 | H30: 2003 | I30: Classic Cars | J30: 214 | K30: =Sales!$B30-Sales!$J30 -> -114 | L30: =(Sales!$J30-Sales!$B30)/Sales!$J30 -> 0.53271028 | M30: =IF(L30<0%,"Below 0%",IF(L30=0%,"0%",IF(AND(L30<=5%,L30>0%),"0%-5%",IF(AND(L30<=10%,L30>5%),"5%-10%",IF(AND(L30<=15%,L30>10%),"10%-15%",IF(AND(L30<=20%,L30>15%),"15%-20%","+20%")))))) -> +20% | N30: Madrid | O30: Spain | P30: EMEA | Q30: Large
A31: 37 | B31: 100 | C31: =Sales!$B31*Sales!$A31 -> 3700 | D31: 37826 | E31: Shipped | F31: 3 | G31: 7 | H31: 2003 | I31: Classic Cars | J31: 214 | K31: =Sales!$B31-Sales!$J31 -> -114 | L31: =(Sales!$J31-Sales!$B31)/Sales!$J31 -> 0.53271028 | M31: =IF(L31<0%,"Below 0%",IF(L31=0%,"0%",IF(AND(L31<=5%,L31>0%),"0%-5%",IF(AND(L31<=10%,L31>5%),"5%-10%",IF(AND(L31<=15%,L31>10%),"10%-15%",IF(AND(L31<=20%,L31>15%),"15%-20%","+20%")))))) -> +20% | N31: Burlingame | O31: USA | P31: NA | Q31: Large
A32: 45 | B32: 100 | C32: =Sales!$B32*Sales!$A32 -> 4500 | D32: 37883 | E32: Shipped | F32: 3 | G32: 9 | H32: 2003 | I32: Classic Cars | J32: 214 | K32: =Sales!$B32-Sales!$J32 -> -114 | L32: =(Sales!$J32-Sales!$B32)/Sales!$J32 -> 0.53271028 | M32: =IF(L32<0%,"Below 0%",IF(L32=0%,"0%",IF(AND(L32<=5%,L32>0%),"0%-5%",IF(AND(L32<=10%,L32>5%),"5%-10%",IF(AND(L32<=15%,L32>10%),"10%-15%",IF(AND(L32<=20%,L32>15%),"15%-20%","+20%")))))) -> +20% | N32: Singapore | O32: Singapore | P32: APAC | Q32: Large
... A55: 50 | B55: 100 | C55: =Sales!$B55*Sales!$A55 -> 5000 | D55: 38503 | E55: In Process | F55: 2 | G55: 5 | H55: 2005 | I55: Classic Cars | J55: 214 | K55: =Sales!$B55-Sales!$J55 -> -114 | L55: =(Sales!$J55-Sales!$B55)/Sales!$J55 -> 0.53271028 | M55: =IF(L55<0%,"Below 0%",IF(L55=0%,"0%",IF(AND(L55<=5%,L55>0%),"0%-5%",IF(AND(L55<=10%,L55>5%),"5%-10%",IF(AND(L55<=15%,L55>10%),"10%-15%",IF(AND(L55<=20%,L55>15%),"15%-20%","+20%")))))) -> +20% | N55: Madrid | O55: Spain | P55: EMEA | Q55: Large
A56: 39 | B56: 99.91 | C56: =Sales!$B56*Sales!$A56 -> 3896.49 | D56: 37676 | E56: Shipped | F56: 1 | G56: 2 | H56: 2003 | I56: Motorcycles | J56: 118 | K56: =Sales!$B56-Sales!$J56 -> -18.09 | L56: =(Sales!$J56-Sales!$B56)/Sales!$J56 -> 0.15330508 | M56: 10%-15% | N56: NYC | O56: USA | P56: NA | Q56: Medium
A57: 29 | B57: 96.34 | C57: =Sales!$B57*Sales!$A57 -> 2793.86 | D57: 37740 | E57: Shipped | F57: 2 | G57: 4 | H57: 2003 | I57: Motorcycles | J57: 118 | K57: =Sales!$B57-Sales!$J57 -> -21.66 | L57: =(Sales!$J57-Sales!$B57)/Sales!$J57 -> 0.18355932 | M57: =IF(L57<0%,"Below 0%",IF(L57=0%,"0%",IF(AND(L57<=5%,L57>0%),"0%-5%",IF(AND(L57<=10%,L57>5%),"5%-10%",IF(AND(L57<=15%,L57>10%),"10%-15%",IF(AND(L57<=20%,L57>15%),"15%-20%","+20%")))))) -> 15%-20% | N57: Melbourne | O57: Australia | P57: APAC | Q57: Small
A58: 27 | B58: 100 | C58: =Sales!$B58*Sales!$A58 -> 2700 | D58: 37803 | E58: Shipped | F58: 3 | G58: 7 | H58: 2003 | I58: Motorcycles | J58: 118 | K58: =Sales!$B58-Sales!$J58 -> -18 | L58: =(Sales!$J58-Sales!$B58)/Sales!$J58 -> 0.15254237 | M58: 10%-15% | N58: Paris | O58: France | P58: EMEA | Q58: Medium
A59: 37 | B59: 100 | C59: =Sales!$B59*Sales!$A59 -> 3700 | D59: 37858 | E59: Shipped | F59: 3 | G59: 8 | H59: 2003 | I59: Motorcycles | J59: 118 | K59: =Sales!$B59-Sales!$J59 -> -18 | L59: =(Sales!$J59-Sales!$B59)/Sales!$J59 -> 0.15254237 | M59: 10%-15% | N59: Pasadena | O59: USA | P59: NA | Q59: Medium
A60: 37 | B60: 100 | C60: =Sales!$B60*Sales!$A60 -> 3700 | D60: 37904 | E60: Shipped | F60: 4 | G60: 10 | H60: 2003 | I60: Motorcycles | J60: 118 | K60: =Sales!$B60-Sales!$J60 -> -18 | L60: =(Sales!$J60-Sales!$B60)/Sales!$J60 -> 0.15254237 | M60: 10%-15% | N60: San Francisco | O60: USA | P60: NA | Q60: Medium
A61: 27 | B61: 100 | C61: =Sales!$B61*Sales!$A61 -> 2700 | D61: 37922 | E61: Shipped | F61: 4 | G61: 10 | H61: 2003 | I61: Motorcycles | J61: 118 | K61: =Sales!$B61-Sales!$J61 -> -18 | L61: =(Sales!$J61-Sales!$B61)/Sales!$J61 -> 0.15254237 | M61: 10%-15% | N61: Burlingame | O61: USA | P61: NA | Q61: Medium
A62: 42 | B62: 100 | C62: =Sales!$B62*Sales!$A62 -> 4200 | D62: 37936 | E62: Shipped | F62: 4 | G62: 11 | H62: 2003 | I62: Motorcycles | J62: 118 | K62: =Sales!$B62-Sales!$J62 -> -18 | L62: =(Sales!$J62-Sales!$B62)/Sales!$J62 -> 0.15254237 | M62: 10%-15% | N62: Lille | O62: France | P62: EMEA | Q62: Medium
A63: 38 | B63: 96.34 | C63: =Sales!$B63*Sales!$A63 -> 3660.92 | D63: 37943 | E63: Shipped | F63: 4 | G63: 11 | H63: 2003 | I63: Motorcycles | J63: 118 | K63: =Sales!$B63-Sales!$J63 -> -21.66 | L63: =(Sales!$J63-Sales!$B63)/Sales!$J63 -> 0.18355932 | M63: =IF(L63<0%,"Below 0%",IF(L63=0%,"0%",IF(AND(L63<=5%,L63>0%),"0%-5%",IF(AND(L63<=10%,L63>5%),"5%-10%",IF(AND(L63<=15%,L63>10%),"10%-15%",IF(AND(L63<=20%,L63>15%),"15%-20%","+20%")))))) -> 15%-20% | N63: Bergen | O63: Norway | P63: EMEA | Q63: Medium
A64: 24 | B64: 100 | C64: =Sales!$B64*Sales!$A64 -> 2400 | D64: 37956 | E64: Shipped | F64: 4 | G64: 12 | H64: 2003 | I64: Motorcycles | J64: 118 | K64: =Sales!$B64-Sales!$J64 -> -18 | L64: =(Sales!$J64-Sales!$B64)/Sales!$J64 -> 0.15254237 | M64: 10%-15% | N64: San Francisco | O64: USA | P64: NA | Q64: Medium
...

Sheet DASHBOARD

Sheet Pivot tables
A1: total sales | E1: AVG Discount | J1: sales by country | O1: sales by city | T1: sales by product | X1: sales over time | AB1: percentage of orders status | AF1: AVG OF quantity | AJ1: discount VS sales | AN1: AVG Of Price Each
A4: Sum of SALES | E4: Average of AVG DISCOUNT | J4: Row Labels | K4: Sum of SALES | O4: Row Labels | P4: Sum of SALES | T4: Row Labels | U4: Sum of SALES | X4: Row Labels | Y4: Sum of SALES | AB4: Row Labels | AC4: Count of STATUS | AF4: Average of QUANTITY ORDERED | AJ4: Row Labels | AK4: Sum of SALES | AN4: Average of PRICE EACH
A5: 8290886.8 | E5: 0.09514055 | J5: USA | K5: 2986425.2 | O5: Madrid | P5: 902094.19 | T5: Classic Cars | U5: 2968546.4 | X5: Jan | Y5: 659582.29 | AB5: Cancelled | AC5: 0.021253985 | AF5: 35.092809 | AJ5: +20% | AK5: 2571729.7 | AN5: 83.658544
J6: Spain | K6: 1021706 | O6: San Rafael | P6: 530587.19 | T6: Vintage Cars | U6: 1644212.1 | X6: Feb | Y6: 668328.15 | AB6: Disputed | AC6: 0.0049592632 | AJ6: 0% | AK6: 173545.19
J7: France | K7: 919257.85 | O7: NYC | P7: 450418.63 | T7: Motorcycles | U7: 971086.29 | X7: Mar | Y7: 626186.73 | AB7: In Process | AC7: 0.014523557 | AG7: =GETPIVOTDATA("QUANTITY ORDERED",$AF$4) -> 35.092809 | AJ7: 0%-5% | AK7: 757938.06 | AO7: =GETPIVOTDATA("PRICE EACH",$AN$4) -> 83.658544
J8: Australia | K8: 521598.46 | O8: Singapore | P8: 227985.5 | T8: Trucks and Buses | U8: 947355.18 | X8: Apr | Y8: 560334.46 | AB8: On Hold | AC8: 0.015586256 | AJ8: 10%-15% | AK8: 1154373.2
B9: =GETPIVOTDATA("SALES",$A$4) -> 8290886.8 | F9: =GETPIVOTDATA("AVG DISCOUNT",$E$4) -> 0.09514055 | J9: UK | K9: 413203.34 | O9: Paris | P9: 212959.82 | T9: Planes | U9: 877942.21 | X9: May | Y9: 756812.91 | AB9: Resolved | AC9: 0.016648955 | AJ9: 15%-20% | AK9: 859087.03
J10: Italy | K10: 309402.87 | O10: San Francisco | P10: 179088.23 | T10: Ships | U10: 677940.4 | X10: Jun | Y10: 384743.59 | AB10: Shipped | AC10: 0.92702798 | AJ10: 5%-10% | AK10: 485914.23
J11: Finland | K11: 268714.7 | O11: Nantes | P11: 175122.98 | T11: Trains | U11: 203804.26 | X11: Jul | Y11: 420973.34 | AB11: Grand Total | AC11: 1 | AJ11: Below 0% | AK11: 2288299.4
J12: Norway | K12: 246115.8 | O12: New Bedford | P12: 172699.65 | T12: Grand Total | U12: 8290886.8 | X12: Aug | Y12: 552132.91 | AJ12: Grand Total | AK12: 8290886.8
J13: Singapore | K13: 227985.5 | O13: Melbourne | P13: 164575.87 | X13: Sep | Y13: 474900.12
J14: Canada | K14: 193504.34 | O14: Brickhaven | P14: 141145.54 | X14: Oct | Y14: 919036.7
J15: Grand Total | K15: 7107914 | O15: Grand Total | P15: 3156677.6 | X15: Nov | Y15: 1744682.4 | AC15: =GETPIVOTDATA("STATUS",$AB$4,"STATUS","Shipped") -> 0.92702798
X16: Dec | Y16: 523173.14 | AC16: =GETPIVOTDATA("STATUS",$AB$4,"STATUS","Cancelled") -> 0.021253985
X17: Grand Total | Y17: 8290886.8 | AC17: =GETPIVOTDATA("STATUS",$AB$4,"STATUS","Resolved") -> 0.016648955
AC18: =GETPIVOTDATA("STATUS",$AB$4,"STATUS","On Hold") -> 0.015586256
AC19: =GETPIVOTDATA("STATUS",$AB$4,"STATUS","In Process") -> 0.014523557
AC20: =GETPIVOTDATA("STATUS",$AB$4,"STATUS","Disputed") -> 0.0049592632
